2013-08-01 11:58:01,575 [ERROR   ] [django.request handle_uncaught_exception:212] Internal Server Error: /
Traceback (most recent call last):
  File "/Library/Python/2.7/site-packages/django/core/handlers/base.py", line 115, in get_response
    response = callback(request, *callback_args, **callback_kwargs)
TypeError: 'str' object is not callable
2013-08-01 11:58:01,819 [WARNING ] [django.request get_response:146] Not Found: /favicon.ico
2013-08-01 11:58:03,995 [ERROR   ] [django.request handle_uncaught_exception:212] Internal Server Error: /
Traceback (most recent call last):
  File "/Library/Python/2.7/site-packages/django/core/handlers/base.py", line 115, in get_response
    response = callback(request, *callback_args, **callback_kwargs)
TypeError: 'str' object is not callable
2013-08-01 11:58:04,187 [WARNING ] [django.request get_response:146] Not Found: /favicon.ico
2013-08-01 11:59:32,412 [ERROR   ] [django.request handle_uncaught_exception:212] Internal Server Error: /
Traceback (most recent call last):
  File "/Library/Python/2.7/site-packages/django/core/handlers/base.py", line 115, in get_response
    response = callback(request, *callback_args, **callback_kwargs)
TypeError: 'str' object is not callable
2013-08-01 11:59:32,656 [WARNING ] [django.request get_response:146] Not Found: /favicon.ico
2013-08-01 11:59:33,628 [ERROR   ] [django.request handle_uncaught_exception:212] Internal Server Error: /
Traceback (most recent call last):
  File "/Library/Python/2.7/site-packages/django/core/handlers/base.py", line 115, in get_response
    response = callback(request, *callback_args, **callback_kwargs)
TypeError: 'str' object is not callable
2013-08-01 11:59:33,805 [WARNING ] [django.request get_response:146] Not Found: /favicon.ico
2013-08-01 12:00:46,682 [ERROR   ] [django.request handle_uncaught_exception:212] Internal Server Error: /
Traceback (most recent call last):
  File "/Library/Python/2.7/site-packages/django/core/handlers/base.py", line 115, in get_response
    response = callback(request, *callback_args, **callback_kwargs)
TypeError: 'str' object is not callable
2013-08-01 12:00:46,932 [WARNING ] [django.request get_response:146] Not Found: /favicon.ico
2013-08-01 12:00:48,074 [ERROR   ] [django.request handle_uncaught_exception:212] Internal Server Error: /
Traceback (most recent call last):
  File "/Library/Python/2.7/site-packages/django/core/handlers/base.py", line 115, in get_response
    response = callback(request, *callback_args, **callback_kwargs)
TypeError: 'str' object is not callable
2013-08-01 12:00:48,251 [WARNING ] [django.request get_response:146] Not Found: /favicon.ico
2013-08-01 12:00:51,592 [ERROR   ] [django.request handle_uncaught_exception:212] Internal Server Error: /
Traceback (most recent call last):
  File "/Library/Python/2.7/site-packages/django/core/handlers/base.py", line 115, in get_response
    response = callback(request, *callback_args, **callback_kwargs)
TypeError: 'str' object is not callable
2013-08-01 12:00:51,757 [WARNING ] [django.request get_response:146] Not Found: /favicon.ico
2013-08-01 12:02:19,762 [ERROR   ] [django.request handle_uncaught_exception:212] Internal Server Error: /
Traceback (most recent call last):
  File "/Library/Python/2.7/site-packages/django/core/handlers/base.py", line 115, in get_response
    response = callback(request, *callback_args, **callback_kwargs)
  File "/Users/imarlier/dev/src/noc-skills/NocSkillsWeb/NocSkillsWeb/views.py", line 11, in index
    response = render_to_response(template_name = 'index.html')
NameError: global name 'render_to_response' is not defined
2013-08-01 12:02:20,013 [WARNING ] [django.request get_response:146] Not Found: /favicon.ico
2013-08-01 12:02:38,796 [ERROR   ] [django.request handle_uncaught_exception:212] Internal Server Error: /
Traceback (most recent call last):
  File "/Library/Python/2.7/site-packages/django/core/handlers/base.py", line 115, in get_response
    response = callback(request, *callback_args, **callback_kwargs)
  File "/Users/imarlier/dev/src/noc-skills/NocSkillsWeb/NocSkillsWeb/views.py", line 11, in index
    response = render(request, 'index.html')
  File "/Library/Python/2.7/site-packages/django/shortcuts/__init__.py", line 53, in render
    return HttpResponse(loader.render_to_string(*args, **kwargs),
  File "/Library/Python/2.7/site-packages/django/template/loader.py", line 170, in render_to_string
    t = get_template(template_name)
  File "/Library/Python/2.7/site-packages/django/template/loader.py", line 146, in get_template
    template, origin = find_template(template_name)
  File "/Library/Python/2.7/site-packages/django/template/loader.py", line 139, in find_template
    raise TemplateDoesNotExist(name)
TemplateDoesNotExist: index.html
2013-08-01 12:02:39,018 [WARNING ] [django.request get_response:146] Not Found: /favicon.ico
2013-08-01 12:04:28,419 [ERROR   ] [django.request handle_uncaught_exception:212] Internal Server Error: /
Traceback (most recent call last):
  File "/Library/Python/2.7/site-packages/django/core/handlers/base.py", line 115, in get_response
    response = callback(request, *callback_args, **callback_kwargs)
  File "/Users/imarlier/dev/src/noc-skills/NocSkillsWeb/NocSkillsWeb/views.py", line 11, in index
    logger.info("Template dirs: %s" % (TEMPLATE_DIRS))
NameError: global name 'TEMPLATE_DIRS' is not defined
2013-08-01 12:04:28,671 [WARNING ] [django.request get_response:146] Not Found: /favicon.ico
2013-08-01 12:08:08,755 [ERROR   ] [django.request handle_uncaught_exception:212] Internal Server Error: /
Traceback (most recent call last):
  File "/Library/Python/2.7/site-packages/django/core/handlers/base.py", line 115, in get_response
    response = callback(request, *callback_args, **callback_kwargs)
  File "/Users/imarlier/dev/src/noc-skills/NocSkillsWeb/NocSkillsWeb/views.py", line 11, in index
    logger.info("Template dirs: %s" % (TEMPLATE_DIRS))
NameError: global name 'TEMPLATE_DIRS' is not defined
2013-08-01 12:08:08,930 [WARNING ] [django.request get_response:146] Not Found: /favicon.ico
2013-08-01 12:08:10,662 [ERROR   ] [django.request handle_uncaught_exception:212] Internal Server Error: /
Traceback (most recent call last):
  File "/Library/Python/2.7/site-packages/django/core/handlers/base.py", line 115, in get_response
    response = callback(request, *callback_args, **callback_kwargs)
  File "/Users/imarlier/dev/src/noc-skills/NocSkillsWeb/NocSkillsWeb/views.py", line 11, in index
    logger.info("Template dirs: %s" % (TEMPLATE_DIRS))
NameError: global name 'TEMPLATE_DIRS' is not defined
2013-08-01 12:08:10,835 [WARNING ] [django.request get_response:146] Not Found: /favicon.ico
2013-08-01 12:08:19,685 [ERROR   ] [django.request handle_uncaught_exception:212] Internal Server Error: /
Traceback (most recent call last):
  File "/Library/Python/2.7/site-packages/django/core/handlers/base.py", line 133, in get_response
    raise ValueError("The view %s.%s didn't return an HttpResponse object." % (callback.__module__, view_name))
ValueError: The view NocSkillsWeb.views.index didn't return an HttpResponse object.
2013-08-01 12:08:19,856 [WARNING ] [django.request get_response:146] Not Found: /favicon.ico
2013-08-01 12:08:53,012 [WARNING ] [django.request get_response:146] Not Found: /favicon.ico
2013-08-01 12:09:05,430 [WARNING ] [django.request get_response:146] Not Found: /favicon.ico
2013-08-01 12:55:04,809 [ERROR   ] [django.request handle_uncaught_exception:212] Internal Server Error: /
Traceback (most recent call last):
  File "/Library/Python/2.7/site-packages/django/core/handlers/base.py", line 115, in get_response
    response = callback(request, *callback_args, **callback_kwargs)
  File "/Users/imarlier/dev/src/noc-skills/NocSkillsWeb/NocSkillsWeb/views.py", line 12, in index
    r = requests.get("http://localhost:8000/list")
  File "/Library/Python/2.7/site-packages/requests/api.py", line 55, in get
    return request('get', url, **kwargs)
  File "/Library/Python/2.7/site-packages/requests/api.py", line 44, in request
    return session.request(method=method, url=url, **kwargs)
  File "/Library/Python/2.7/site-packages/requests/sessions.py", line 354, in request
    resp = self.send(prep, **send_kwargs)
  File "/Library/Python/2.7/site-packages/requests/sessions.py", line 460, in send
    r = adapter.send(request, **kwargs)
  File "/Library/Python/2.7/site-packages/requests/adapters.py", line 246, in send
    raise ConnectionError(e)
ConnectionError: HTTPConnectionPool(host='localhost', port=8000): Max retries exceeded with url: /list (Caused by <class 'socket.error'>: [Errno 61] Connection refused)
2013-08-01 12:55:05,110 [WARNING ] [django.request get_response:146] Not Found: /favicon.ico
2013-08-01 12:55:31,622 [WARNING ] [django.request get_response:146] Not Found: /favicon.ico
2013-08-01 12:57:42,855 [WARNING ] [django.request get_response:146] Not Found: /favicon.ico
2013-08-01 13:00:16,262 [INFO    ] [requests.packages.urllib3.connectionpool _new_conn:195] Starting new HTTP connection (1): localhost
2013-08-01 13:00:16,267 [DEBUG   ] [requests.packages.urllib3.connectionpool _make_request:289] "GET /list HTTP/1.1" 200 None
2013-08-01 13:00:16,268 [INFO    ] [NocSkillsWeb.views index:13] Request for list of reasons gave status code 200
2013-08-01 13:00:16,366 [WARNING ] [django.request get_response:146] Not Found: /favicon.ico
2013-08-01 13:00:16,366 [WARNING ] [django.request get_response:146] Not Found: /favicon.ico
2013-08-01 13:08:08,041 [INFO    ] [requests.packages.urllib3.connectionpool _new_conn:195] Starting new HTTP connection (1): localhost
2013-08-01 13:08:08,045 [DEBUG   ] [requests.packages.urllib3.connectionpool _make_request:289] "GET /list HTTP/1.1" 200 None
2013-08-01 13:08:08,046 [INFO    ] [NocSkillsWeb.views index:20] Request for list of reasons gave status code 200
2013-08-01 13:08:08,215 [WARNING ] [django.request get_response:146] Not Found: /favicon.ico
2013-08-01 13:08:08,215 [WARNING ] [django.request get_response:146] Not Found: /favicon.ico
2013-08-01 13:08:22,613 [INFO    ] [requests.packages.urllib3.connectionpool _new_conn:195] Starting new HTTP connection (1): localhost
2013-08-01 13:08:22,614 [ERROR   ] [django.request handle_uncaught_exception:212] Internal Server Error: /
Traceback (most recent call last):
  File "/Library/Python/2.7/site-packages/django/core/handlers/base.py", line 115, in get_response
    response = callback(request, *callback_args, **callback_kwargs)
  File "/Users/imarlier/dev/src/noc-skills/NocSkillsWeb/NocSkillsWeb/views.py", line 17, in index
    except ConnectionException, e:
NameError: global name 'ConnectionException' is not defined
2013-08-01 13:08:22,614 [ERROR   ] [django.request handle_uncaught_exception:212] Internal Server Error: /
Traceback (most recent call last):
  File "/Library/Python/2.7/site-packages/django/core/handlers/base.py", line 115, in get_response
    response = callback(request, *callback_args, **callback_kwargs)
  File "/Users/imarlier/dev/src/noc-skills/NocSkillsWeb/NocSkillsWeb/views.py", line 17, in index
    except ConnectionException, e:
NameError: global name 'ConnectionException' is not defined
2013-08-01 13:08:22,805 [WARNING ] [django.request get_response:146] Not Found: /favicon.ico
2013-08-01 13:08:22,805 [WARNING ] [django.request get_response:146] Not Found: /favicon.ico
2013-08-01 13:10:36,899 [INFO    ] [requests.packages.urllib3.connectionpool _new_conn:195] Starting new HTTP connection (1): localhost
2013-08-01 13:10:36,900 [ERROR   ] [django.request handle_uncaught_exception:212] Internal Server Error: /
Traceback (most recent call last):
  File "/Library/Python/2.7/site-packages/django/core/handlers/base.py", line 115, in get_response
    response = callback(request, *callback_args, **callback_kwargs)
  File "/Users/imarlier/dev/src/noc-skills/NocSkillsWeb/NocSkillsWeb/views.py", line 17, in index
    except ConnectionError, e:
NameError: global name 'ConnectionError' is not defined
2013-08-01 13:10:36,900 [ERROR   ] [django.request handle_uncaught_exception:212] Internal Server Error: /
Traceback (most recent call last):
  File "/Library/Python/2.7/site-packages/django/core/handlers/base.py", line 115, in get_response
    response = callback(request, *callback_args, **callback_kwargs)
  File "/Users/imarlier/dev/src/noc-skills/NocSkillsWeb/NocSkillsWeb/views.py", line 17, in index
    except ConnectionError, e:
NameError: global name 'ConnectionError' is not defined
2013-08-01 13:10:37,151 [WARNING ] [django.request get_response:146] Not Found: /favicon.ico
2013-08-01 13:10:37,151 [WARNING ] [django.request get_response:146] Not Found: /favicon.ico
2013-08-01 13:10:39,009 [INFO    ] [requests.packages.urllib3.connectionpool _new_conn:195] Starting new HTTP connection (1): localhost
2013-08-01 13:10:39,010 [ERROR   ] [django.request handle_uncaught_exception:212] Internal Server Error: /
Traceback (most recent call last):
  File "/Library/Python/2.7/site-packages/django/core/handlers/base.py", line 115, in get_response
    response = callback(request, *callback_args, **callback_kwargs)
  File "/Users/imarlier/dev/src/noc-skills/NocSkillsWeb/NocSkillsWeb/views.py", line 17, in index
    except ConnectionError, e:
NameError: global name 'ConnectionError' is not defined
2013-08-01 13:10:39,010 [ERROR   ] [django.request handle_uncaught_exception:212] Internal Server Error: /
Traceback (most recent call last):
  File "/Library/Python/2.7/site-packages/django/core/handlers/base.py", line 115, in get_response
    response = callback(request, *callback_args, **callback_kwargs)
  File "/Users/imarlier/dev/src/noc-skills/NocSkillsWeb/NocSkillsWeb/views.py", line 17, in index
    except ConnectionError, e:
NameError: global name 'ConnectionError' is not defined
2013-08-01 13:10:39,199 [WARNING ] [django.request get_response:146] Not Found: /favicon.ico
2013-08-01 13:10:39,199 [WARNING ] [django.request get_response:146] Not Found: /favicon.ico
2013-08-01 13:10:50,376 [INFO    ] [requests.packages.urllib3.connectionpool _new_conn:195] Starting new HTTP connection (1): localhost
2013-08-01 13:10:50,378 [ERROR   ] [NocSkillsWeb.views index:18] Unable to load list of data from http://localhost:8000/list: HTTPConnectionPool(host='localhost', port=8000): Max retries exceeded with url: /list (Caused by <class 'socket.error'>: [Errno 61] Connection refused)
2013-08-01 13:10:50,469 [WARNING ] [django.request get_response:146] Not Found: /favicon.ico
2013-08-01 13:10:50,469 [WARNING ] [django.request get_response:146] Not Found: /favicon.ico
2013-08-01 13:17:59,302 [INFO    ] [requests.packages.urllib3.connectionpool _new_conn:195] Starting new HTTP connection (1): localhost
2013-08-01 13:17:59,412 [DEBUG   ] [requests.packages.urllib3.connectionpool _make_request:289] "GET /list HTTP/1.1" 200 None
2013-08-01 13:17:59,416 [INFO    ] [NocSkillsWeb.views index:24] Reasons: [{u'reason': u"Working at HubSpot, you'll regularly be exposed to new technologies, and you'll find your horizons expanding as you learn python, Java, Javascript, and the intricacies of cloud operations", u'name': u'Exposure', u'imageURL': None}]
2013-08-01 13:17:59,589 [WARNING ] [django.request get_response:146] Not Found: /favicon.ico
2013-08-01 13:17:59,589 [WARNING ] [django.request get_response:146] Not Found: /favicon.ico
2013-08-01 13:26:58,760 [INFO    ] [requests.packages.urllib3.connectionpool _new_conn:195] Starting new HTTP connection (1): localhost
2013-08-01 13:26:58,770 [DEBUG   ] [requests.packages.urllib3.connectionpool _make_request:289] "GET /list HTTP/1.1" 200 None
2013-08-01 13:26:58,771 [INFO    ] [NocSkillsWeb.views index:24] Reasons: [{u'reason': u"Working at HubSpot, you'll regularly be exposed to new technologies, and you'll find your horizons expanding as you learn python, Java, Javascript, and the intricacies of cloud operations", u'name': u'Exposure', u'imageURL': None}]
2013-08-01 13:26:58,772 [ERROR   ] [django.request handle_uncaught_exception:212] Internal Server Error: /
Traceback (most recent call last):
  File "/Library/Python/2.7/site-packages/django/core/handlers/base.py", line 115, in get_response
    response = callback(request, *callback_args, **callback_kwargs)
  File "/Users/imarlier/dev/src/noc-skills/NocSkillsWeb/NocSkillsWeb/views.py", line 25, in index
    return render(request, 'index.html', {'reasons': reasons})
  File "/Library/Python/2.7/site-packages/django/shortcuts/__init__.py", line 53, in render
    return HttpResponse(loader.render_to_string(*args, **kwargs),
  File "/Library/Python/2.7/site-packages/django/template/loader.py", line 170, in render_to_string
    t = get_template(template_name)
  File "/Library/Python/2.7/site-packages/django/template/loader.py", line 146, in get_template
    template, origin = find_template(template_name)
  File "/Library/Python/2.7/site-packages/django/template/loader.py", line 135, in find_template
    source, display_name = loader(name, dirs)
  File "/Library/Python/2.7/site-packages/django/template/loader.py", line 43, in __call__
    return self.load_template(template_name, template_dirs)
  File "/Library/Python/2.7/site-packages/django/template/loader.py", line 49, in load_template
    template = get_template_from_string(source, origin, template_name)
  File "/Library/Python/2.7/site-packages/django/template/loader.py", line 157, in get_template_from_string
    return Template(source, origin, name)
  File "/Library/Python/2.7/site-packages/django/template/base.py", line 125, in __init__
    self.nodelist = compile_string(template_string, origin)
  File "/Library/Python/2.7/site-packages/django/template/base.py", line 153, in compile_string
    return parser.parse()
  File "/Library/Python/2.7/site-packages/django/template/base.py", line 274, in parse
    compiled_result = compile_func(self, token)
  File "/Library/Python/2.7/site-packages/django/template/defaulttags.py", line 767, in do_for
    nodelist_loop = parser.parse(('empty', 'endfor',))
  File "/Library/Python/2.7/site-packages/django/template/base.py", line 274, in parse
    compiled_result = compile_func(self, token)
  File "/Library/Python/2.7/site-packages/django/template/defaulttags.py", line 902, in do_if
    condition = TemplateIfParser(parser, bits).parse()
  File "/Library/Python/2.7/site-packages/django/template/smartif.py", line 191, in parse
    self.current_token.display())
TemplateSyntaxError: Unused 'is' at end of if expression.
2013-08-01 13:26:58,772 [ERROR   ] [django.request handle_uncaught_exception:212] Internal Server Error: /
Traceback (most recent call last):
  File "/Library/Python/2.7/site-packages/django/core/handlers/base.py", line 115, in get_response
    response = callback(request, *callback_args, **callback_kwargs)
  File "/Users/imarlier/dev/src/noc-skills/NocSkillsWeb/NocSkillsWeb/views.py", line 25, in index
    return render(request, 'index.html', {'reasons': reasons})
  File "/Library/Python/2.7/site-packages/django/shortcuts/__init__.py", line 53, in render
    return HttpResponse(loader.render_to_string(*args, **kwargs),
  File "/Library/Python/2.7/site-packages/django/template/loader.py", line 170, in render_to_string
    t = get_template(template_name)
  File "/Library/Python/2.7/site-packages/django/template/loader.py", line 146, in get_template
    template, origin = find_template(template_name)
  File "/Library/Python/2.7/site-packages/django/template/loader.py", line 135, in find_template
    source, display_name = loader(name, dirs)
  File "/Library/Python/2.7/site-packages/django/template/loader.py", line 43, in __call__
    return self.load_template(template_name, template_dirs)
  File "/Library/Python/2.7/site-packages/django/template/loader.py", line 49, in load_template
    template = get_template_from_string(source, origin, template_name)
  File "/Library/Python/2.7/site-packages/django/template/loader.py", line 157, in get_template_from_string
    return Template(source, origin, name)
  File "/Library/Python/2.7/site-packages/django/template/base.py", line 125, in __init__
    self.nodelist = compile_string(template_string, origin)
  File "/Library/Python/2.7/site-packages/django/template/base.py", line 153, in compile_string
    return parser.parse()
  File "/Library/Python/2.7/site-packages/django/template/base.py", line 274, in parse
    compiled_result = compile_func(self, token)
  File "/Library/Python/2.7/site-packages/django/template/defaulttags.py", line 767, in do_for
    nodelist_loop = parser.parse(('empty', 'endfor',))
  File "/Library/Python/2.7/site-packages/django/template/base.py", line 274, in parse
    compiled_result = compile_func(self, token)
  File "/Library/Python/2.7/site-packages/django/template/defaulttags.py", line 902, in do_if
    condition = TemplateIfParser(parser, bits).parse()
  File "/Library/Python/2.7/site-packages/django/template/smartif.py", line 191, in parse
    self.current_token.display())
TemplateSyntaxError: Unused 'is' at end of if expression.
2013-08-01 13:26:59,067 [WARNING ] [django.request get_response:146] Not Found: /favicon.ico
2013-08-01 13:26:59,067 [WARNING ] [django.request get_response:146] Not Found: /favicon.ico
2013-08-01 13:27:11,943 [INFO    ] [requests.packages.urllib3.connectionpool _new_conn:195] Starting new HTTP connection (1): localhost
2013-08-01 13:27:11,948 [DEBUG   ] [requests.packages.urllib3.connectionpool _make_request:289] "GET /list HTTP/1.1" 200 None
2013-08-01 13:27:11,949 [INFO    ] [NocSkillsWeb.views index:24] Reasons: [{u'reason': u"Working at HubSpot, you'll regularly be exposed to new technologies, and you'll find your horizons expanding as you learn python, Java, Javascript, and the intricacies of cloud operations", u'name': u'Exposure', u'imageURL': None}]
2013-08-01 13:27:12,059 [WARNING ] [django.request get_response:146] Not Found: /favicon.ico
2013-08-01 13:27:12,059 [WARNING ] [django.request get_response:146] Not Found: /favicon.ico
